Workbook

Sheet project
A1: key | B1: value | C1: 备注
A2: product_type | B2: TEST_EMS | C2: 项目类型
A3: project | B3: 鸿合EMS测试平台 | C3: 项目名称：
A4: http_ip | B4: 0.0.0.0 | C4: HTTP监听IP
A5: http_port | B5: 9091 | C5: HTTP监听端口
A6: mqtt_host | B6: 127.0.0.1 | C6: MQTT服务器地址
A7: mqtt_port | B7: 1883 | C7: MQTT服务器端口
A8: mqtt_username | B8: root | C8: MQTT用户名
A9: mqtt_password | B9: inpower | C9: MQTT密码
A10: mqtt_yt | B10: /asw/+/+/setyt | C10: MQTT遥调
A11: mqtt_yk | B11: /asw/+/+/setyk | C11: MQTT遥控
A12: north_modbus_host | B12: 0.0.0.0 | C12: 北向Modbus从机IP
A13: north_modbus_port | B13: 9092 | C13: 北向Modbus从机端口
A14: north_modbus_conf | B14: ./config/MODBUS_REGISTERS.xlsx | C14: 北向Modbus配置文件

Sheet devices
A1: no | B1: id | C1: type | D1: desc
A2: 1 | B2: pcs1 | C2: PCS | D2: 1.725MW
A3: 2 | B3: pcs2 | C3: PCS | D3: 1.725MW
A4: 3 | B4: pcs3 | C4: PCS | D4: 1.725MW
A5: 4 | B5: pcs4 | C5: PCS | D5: 1.725MW
A6: 5 | B6: bcu1 | C6: BCU | D6: 鸿合自研
A7: 6 | B7: bcu2 | C7: BCU | D7: 鸿合自研
A8: 7 | B8: bcu3 | C8: BCU | D8: 鸿合自研
A9: 8 | B9: bcu4 | C9: BCU | D9: 鸿合自研
A10: 9 | B10: crd | C10: CRD | D10: 测控柜

Sheet config
A1: no | B1: id | C1: type | D1: comType | E1: registerFile | F1: interval | G1: timeout | H1: ip | I1: port | J1: slave | K1: serialTty | L1: baudRate | M1: dataBits | N1: parity | O1: stopBits | P1: interface | Q1: desc | R1: requestInterval | S1: maxGap
A2: =devices!A2 -> 1 | B2: pcs1 | C2: PCS | D2: ModbusTCP | E2: ./config/PCS_英博_大机.xlsx | F2: 1000 | G2: 1000 | H2: 192.168.0.1 | I2: 502 | J2: 1 | R2: 50
A3: =devices!A3 -> 2 | B3: pcs2 | C3: PCS | D3: ModbusTCP | E3: ./config/PCS_英博_大机.xlsx | F3: 1000 | G3: 1000 | H3: 192.168.0.2 | I3: 502 | J3: 1 | R3: 50
A4: =devices!A4 -> 3 | B4: pcs3 | C4: PCS | D4: ModbusTCP | E4: ./config/PCS_英博_大机.xlsx | F4: 1000 | G4: 1000 | H4: 192.168.0.3 | I4: 502 | J4: 1 | R4: 50
A5: =devices!A5 -> 4 | B5: pcs4 | C5: PCS | D5: ModbusTCP | E5: ./config/PCS_英博_大机.xlsx | F5: 1000 | G5: 1000 | H5: 192.168.0.4 | I5: 502 | J5: 1 | R5: 50
A6: =devices!A6 -> 5 | B6: fire | C6: BCU | D6: ModbusTCP | E6: ./config/BMS_鸿合国轩.xlsx | F6: 1000 | G6: 5000 | H6: 192.168.0.6 | I6: 502 | J6: 1 | S6: 5

Sheet mqtt_routes
A1: device_id | B1: topic | C1: point_ids | D1: enable
A2: pcs1 | B2: /pds/pcs/0/yx | C2: =_xlfn.TEXTJOIN(",",TRUE,[1]遥测!$A$56:$A$71)&",65535" -> 58,59,60,61,62,63,64,65,66,67,68,69,70,71,65535 | D2: 1
A3: pcs1 | B3: /pds/pcs/0/yc | C3: =_xlfn.TEXTJOIN(",",TRUE,[1]遥测!$A$2:$A$55) -> 1,2,3,4,5,6,7,8,9,10,11,12,13,14,15,16,17,18,19,20,21,22,23,24,25,26,27,28,29,30,31,32,33,34,35,36,40,41,42,43,44,45,46,47,48,49,50,51,52,53,54,55,56,57 | D3: 1
A4: pcs1 | B4: /pds/pcs/0/yt | C4: =_xlfn.TEXTJOIN(",",TRUE,[1]遥调!$A$2:$A$31) -> 2000,2001,2002,2003,2004,2005,2006,2007,2008,2009,2010,2011,2012,2013,2014,2015,2016,2017,2018,2019,2020,2021,2022,2023,2024,2025,2026,2027,2028,2029 | D4: 1
A5: pcs2 | B5: /pds/pcs/1/yx | C5: =_xlfn.TEXTJOIN(",",TRUE,[1]遥测!$A$56:$A$71)&",65535" -> 58,59,60,61,62,63,64,65,66,67,68,69,70,71,65535 | D5: 1
A6: pcs2 | B6: /pds/pcs/1/yc | C6: 1,2,3,4,5,6,7,8,9,10,11,12,13,14,15,16,17,18,19,20,21,22,23,24,25,26,27,28,29,30,31,32,33,34,35,36,40,41,42,43,44,45,46,47,48,49,50,51,52,53,54,55,56,57 | D6: 1
A7: pcs2 | B7: /pds/pcs/1/yt | C7: 2000,2001,2002,2003,2004,2005,2006,2007,2008,2009,2010,2011,2012,2013,2014,2015,2016,2017,2018,2019,2020,2021,2022,2023,2024,2025,2026,2027,2028,2029 | D7: 1
A8: pcs3 | B8: /pds/pcs/2/yx | C8: =_xlfn.TEXTJOIN(",",TRUE,[1]遥测!$A$56:$A$71)&",65535" -> 58,59,60,61,62,63,64,65,66,67,68,69,70,71,65535 | D8: 1
A9: pcs3 | B9: /pds/pcs/2/yc | C9: 1,2,3,4,5,6,7,8,9,10,11,12,13,14,15,16,17,18,19,20,21,22,23,24,25,26,27,28,29,30,31,32,33,34,35,36,40,41,42,43,44,45,46,47,48,49,50,51,52,53,54,55,56,57 | D9: 1
A10: pcs3 | B10: /pds/pcs/2/yt | C10: 2000,2001,2002,2003,2004,2005,2006,2007,2008,2009,2010,2011,2012,2013,2014,2015,2016,2017,2018,2019,2020,2021,2022,2023,2024,2025,2026,2027,2028,2029 | D10: 1
A11: pcs4 | B11: /pds/pcs/3/yx | C11: =_xlfn.TEXTJOIN(",",TRUE,[1]遥测!$A$56:$A$71)&",65535" -> 58,59,60,61,62,63,64,65,66,67,68,69,70,71,65535 | D11: 1
A12: pcs4 | B12: /pds/pcs/3/yc | C12: 1,2,3,4,5,6,7,8,9,10,11,12,13,14,15,16,17,18,19,20,21,22,23,24,25,26,27,28,29,30,31,32,33,34,35,36,40,41,42,43,44,45,46,47,48,49,50,51,52,53,54,55,56,57 | D12: 1
A13: pcs4 | B13: /pds/pcs/3/yt | C13: 2000,2001,2002,2003,2004,2005,2006,2007,2008,2009,2010,2011,2012,2013,2014,2015,2016,2017,2018,2019,2020,2021,2022,2023,2024,2025,2026,2027,2028,2029 | D13: 1
A14: bcu1 | B14: /pds/bank/0/yx | C14: =_xlfn.TEXTJOIN(",",TRUE,[3]遥信!$A$2:$A$141,[3]遥测!$A$300:$A$317)&",65535" -> 1000,1001,1002,1003,1004,1005,1006,1007,1008,1009,1010,1011,1012,1013,1014,1015,1016,1017,1018,1019,1020,1021,1022,1023,1024,1025,1026,1027,1028,1029,1030,1031,1032,1033,1034,1035,1036,1037,1038,1039,1040,1041,1042,1043,1044,1045,1046,1047,1048,1049,1050,1051,1052,1053,1054,1055,1056,1057,1058,1059,1060,1061,1062,1063,1064,1065,1066,1067,1068,1069,1070,1071,1072,1073,1074,1075,1076,1077,1078,1079,1080,1081,1082,1083,1084,1085,1086,1087,1088,1089,1090,1091,1092,1093,1094,1095,1096,1097,1098,1099,1100,1101,1102,1103,1104,1105,1106,1107,1108,1109,1110,1111,1112,1113,1114,1115,1116,1117,1118,1119,1120,1121,1122,1123,1124,1125,1126,1127,1128,1129,1130,1131,1132,1133,1134,1135,1136,1137,1138,1139,600,601,602,603,604,605,606,607,608,609,610,611,612,613,614,615,616,617,65535 | D14: 1
A15: bcu1 | B15: /pds/bank/0/yc | C15: =_xlfn.TEXTJOIN(",",TRUE,[3]遥测!$A$2:$A$53) -> 1,2,3,4,5,6,7,8,9,10,11,12,13,14,15,16,17,18,19,20,21,22,23,24,25,26,27,28,29,30,31,32,33,34,35,36,37,38,39,40,41,42,43,44,45,46,47,48,49,50,51,52 | D15: 1
A16: bcu1 | B16: /pds/bank/0/yt | C16: =_xlfn.TEXTJOIN(",",TRUE,[3]遥调!$A$2:$A$20) -> 2000,2001,2002,2003,2004,2005,2006,2007,2008,2009,2010,2011,2012,2013,2014,2015,2016,2017,2018 | D16: 1
A17: bcu2 | B17: /pds/bank/1/yx | C17: =_xlfn.TEXTJOIN(",",TRUE,[3]遥信!$A$2:$A$141,[3]遥测!$A$300:$A$317)&",65535" -> 1000,1001,1002,1003,1004,1005,1006,1007,1008,1009,1010,1011,1012,1013,1014,1015,1016,1017,1018,1019,1020,1021,1022,1023,1024,1025,1026,1027,1028,1029,1030,1031,1032,1033,1034,1035,1036,1037,1038,1039,1040,1041,1042,1043,1044,1045,1046,1047,1048,1049,1050,1051,1052,1053,1054,1055,1056,1057,1058,1059,1060,1061,1062,1063,1064,1065,1066,1067,1068,1069,1070,1071,1072,1073,1074,1075,1076,1077,1078,1079,1080,1081,1082,1083,1084,1085,1086,1087,1088,1089,1090,1091,1092,1093,1094,1095,1096,1097,1098,1099,1100,1101,1102,1103,1104,1105,1106,1107,1108,1109,1110,1111,1112,1113,1114,1115,1116,1117,1118,1119,1120,1121,1122,1123,1124,1125,1126,1127,1128,1129,1130,1131,1132,1133,1134,1135,1136,1137,1138,1139,600,601,602,603,604,605,606,607,608,609,610,611,612,613,614,615,616,617,65535 | D17: 1
A18: bcu2 | B18: /pds/bank/1/yc | C18: =_xlfn.TEXTJOIN(",",TRUE,[3]遥测!$A$2:$A$53) -> 1,2,3,4,5,6,7,8,9,10,11,12,13,14,15,16,17,18,19,20,21,22,23,24,25,26,27,28,29,30,31,32,33,34,35,36,37,38,39,40,41,42,43,44,45,46,47,48,49,50,51,52 | D18: 1
A19: bcu2 | B19: /pds/bank/1/yt | C19: =_xlfn.TEXTJOIN(",",TRUE,[3]遥调!$A$2:$A$20) -> 2000,2001,2002,2003,2004,2005,2006,2007,2008,2009,2010,2011,2012,2013,2014,2015,2016,2017,2018 | D19: 1
A20: bcu3 | B20: /pds/bank/2/yx | C20: =_xlfn.TEXTJOIN(",",TRUE,[3]遥信!$A$2:$A$141,[3]遥测!$A$300:$A$317)&",65535" -> 1000,1001,1002,1003,1004,1005,1006,1007,1008,1009,1010,1011,1012,1013,1014,1015,1016,1017,1018,1019,1020,1021,1022,1023,1024,1025,1026,1027,1028,1029,1030,1031,1032,1033,1034,1035,1036,1037,1038,1039,1040,1041,1042,1043,1044,1045,1046,1047,1048,1049,1050,1051,1052,1053,1054,1055,1056,1057,1058,1059,1060,1061,1062,1063,1064,1065,1066,1067,1068,1069,1070,1071,1072,1073,1074,1075,1076,1077,1078,1079,1080,1081,1082,1083,1084,1085,1086,1087,1088,1089,1090,1091,1092,1093,1094,1095,1096,1097,1098,1099,1100,1101,1102,1103,1104,1105,1106,1107,1108,1109,1110,1111,1112,1113,1114,1115,1116,1117,1118,1119,1120,1121,1122,1123,1124,1125,1126,1127,1128,1129,1130,1131,1132,1133,1134,1135,1136,1137,1138,1139,600,601,602,603,604,605,606,607,608,609,610,611,612,613,614,615,616,617,65535 | D20: 1
A21: bcu3 | B21: /pds/bank/2/yc | C21: 1,2,3,4,5,6,7,8,9,10,11,12,13,14,15,16,17,18,19,20,21,22,23,24,25,26,27,28,29,30,31,32,33,34,35,36,37,38,39,40,41,42,43,44,45,46,47,48,49,50,51,52 | D21: 1
A22: bcu3 | B22: /pds/bank/2/yt | C22: 2000,2001,2002,2003,2004,2005,2006,2007,2008,2009,2010,2011,2012,2013,2014,2015,2016,2017,2018 | D22: 1
A23: bcu4 | B23: /pds/bank/3/yx | C23: =_xlfn.TEXTJOIN(",",TRUE,[3]遥信!$A$2:$A$141,[3]遥测!$A$300:$A$317)&",65535" -> 1000,1001,1002,1003,1004,1005,1006,1007,1008,1009,1010,1011,1012,1013,1014,1015,1016,1017,1018,1019,1020,1021,1022,1023,1024,1025,1026,1027,1028,1029,1030,1031,1032,1033,1034,1035,1036,1037,1038,1039,1040,1041,1042,1043,1044,1045,1046,1047,1048,1049,1050,1051,1052,1053,1054,1055,1056,1057,1058,1059,1060,1061,1062,1063,1064,1065,1066,1067,1068,1069,1070,1071,1072,1073,1074,1075,1076,1077,1078,1079,1080,1081,1082,1083,1084,1085,1086,1087,1088,1089,1090,1091,1092,1093,1094,1095,1096,1097,1098,1099,1100,1101,1102,1103,1104,1105,1106,1107,1108,1109,1110,1111,1112,1113,1114,1115,1116,1117,1118,1119,1120,1121,1122,1123,1124,1125,1126,1127,1128,1129,1130,1131,1132,1133,1134,1135,1136,1137,1138,1139,600,601,602,603,604,605,606,607,608,609,610,611,612,613,614,615,616,617,65535 | D23: 1
A24: bcu4 | B24: /pds/bank/3/yc | C24: 1,2,3,4,5,6,7,8,9,10,11,12,13,14,15,16,17,18,19,20,21,22,23,24,25,26,27,28,29,30,31,32,33,34,35,36,37,38,39,40,41,42,43,44,45,46,47,48,49,50,51,52 | D24: 1
A25: bcu4 | B25: /pds/bank/3/yt | C25: 2000,2001,2002,2003,2004,2005,2006,2007,2008,2009,2010,2011,2012,2013,2014,2015,2016,2017,2018 | D25: 1
A26: bcu1 | B26: /pds/bank/0/rack/0/yc | C26: =_xlfn.TEXTJOIN(",",TRUE,[3]遥测!$A$54:$A$92) -> 100,101,102,103,104,105,106,107,108,109,110,111,112,113,114,115,116,117,118,119,120,121,122,123,124,125,126,127,128,129,130,131,132,133,134,135,136,137,138 | D26: 1
A27: bcu1 | B27: /pds/bank/0/rack/1/yc | C27: =_xlfn.TEXTJOIN(",",TRUE,[3]遥测!$A$93:$A$131) -> 139,140,141,142,143,144,145,146,147,148,149,150,151,152,153,154,155,156,157,158,159,160,161,162,163,164,165,166,167,168,169,170,171,172,173,174,175,176,177 | D27: 1
A28: bcu1 | B28: /pds/bank/0/rack/2/yc | C28: =_xlfn.TEXTJOIN(",",TRUE,[3]遥测!$A$132:$A$170) -> 178,179,180,181,182,183,184,185,186,187,188,189,190,191,192,193,194,195,196,197,198,199,200,201,202,203,204,205,206,207,208,209,210,211,212,213,214,215,216 | D28: 1
A29: bcu1 | B29: /pds/bank/0/rack/3/yc | C29: =_xlfn.TEXTJOIN(",",TRUE,[3]遥测!$A$171:$A$209) -> 217,218,219,220,221,222,223,224,225,226,227,228,229,230,231,232,233,234,235,236,237,238,239,240,241,242,243,244,245,246,247,248,249,250,251,252,253,254,255 | D29: 1
A30: bcu1 | B30: /pds/bank/0/rack/4/yc | C30: =_xlfn.TEXTJOIN(",",TRUE,[3]遥测!$A$210:$A$248) -> 256,257,258,259,260,261,262,263,264,265,266,267,268,269,270,271,272,273,274,275,276,277,278,279,280,281,282,283,284,285,286,287,288,289,290,291,292,293,294 | D30: 1
A31: bcu1 | B31: /pds/bank/0/rack/5/yc | C31: =_xlfn.TEXTJOIN(",",TRUE,[3]遥测!$A$249:$A$287) -> 295,296,297,298,299,300,301,302,303,304,305,306,307,308,309,310,311,312,313,314,315,316,317,318,319,320,321,322,323,324,325,326,327,328,329,330,331,332,333 | D31: 1
A32: bcu2 | B32: /pds/bank/1/rack/0/yc | C32: 100,101,102,103,104,105,106,107,108,109,110,111,112,113,114,115,116,117,118,119,120,121,122,123,124,125,126,127,128,129,130,131,132,133,134,135,136,137,138 | D32: 1
A33: bcu2 | B33: /pds/bank/1/rack/1/yc | C33: 139,140,141,142,143,144,145,146,147,148,149,150,151,152,153,154,155,156,157,158,159,160,161,162,163,164,165,166,167,168,169,170,171,172,173,174,175,176,177 | D33: 1
A34: bcu2 | B34: /pds/bank/1/rack/2/yc | C34: 178,179,180,181,182,183,184,185,186,187,188,189,190,191,192,193,194,195,196,197,198,199,200,201,202,203,204,205,206,207,208,209,210,211,212,213,214,215,216 | D34: 1
A35: bcu2 | B35: /pds/bank/1/rack/3/yc | C35: 217,218,219,220,221,222,223,224,225,226,227,228,229,230,231,232,233,234,235,236,237,238,239,240,241,242,243,244,245,246,247,248,249,250,251,252,253,254,255 | D35: 1
A36: bcu2 | B36: /pds/bank/1/rack/4/yc | C36: 256,257,258,259,260,261,262,263,264,265,266,267,268,269,270,271,272,273,274,275,276,277,278,279,280,281,282,283,284,285,286,287,288,289,290,291,292,293,294 | D36: 1
A37: bcu2 | B37: /pds/bank/1/rack/5/yc | C37: 295,296,297,298,299,300,301,302,303,304,305,306,307,308,309,310,311,312,313,314,315,316,317,318,319,320,321,322,323,324,325,326,327,328,329,330,331,332,333 | D37: 1
A38: bcu3 | B38: /pds/bank/2/rack/0/yc | C38: =_xlfn.TEXTJOIN(",",TRUE,[3]遥测!$A$54:$A$92) -> 100,101,102,103,104,105,106,107,108,109,110,111,112,113,114,115,116,117,118,119,120,121,122,123,124,125,126,127,128,129,130,131,132,133,134,135,136,137,138 | D38: 1
A39: bcu3 | B39: /pds/bank/2/rack/1/yc | C39: =_xlfn.TEXTJOIN(",",TRUE,[3]遥测!$A$93:$A$131) -> 139,140,141,142,143,144,145,146,147,148,149,150,151,152,153,154,155,156,157,158,159,160,161,162,163,164,165,166,167,168,169,170,171,172,173,174,175,176,177 | D39: 1
A40: bcu3 | B40: /pds/bank/2/rack/2/yc | C40: =_xlfn.TEXTJOIN(",",TRUE,[3]遥测!$A$132:$A$170) -> 178,179,180,181,182,183,184,185,186,187,188,189,190,191,192,193,194,195,196,197,198,199,200,201,202,203,204,205,206,207,208,209,210,211,212,213,214,215,216 | D40: 1
...
